[2022-05-16 10:01:13,426] {taskinstance.py:1159} INFO - Dependencies all met for <TaskInstance: Collect_Data_Dag.get_data_src_impacted_country_week_wise scheduled__2022-05-12T18:00:00+00:00 [queued]>
[2022-05-16 10:01:13,435] {taskinstance.py:1159} INFO - Dependencies all met for <TaskInstance: Collect_Data_Dag.get_data_src_impacted_country_week_wise scheduled__2022-05-12T18:00:00+00:00 [queued]>
[2022-05-16 10:01:13,436] {taskinstance.py:1356} INFO - 
--------------------------------------------------------------------------------
[2022-05-16 10:01:13,437] {taskinstance.py:1357} INFO - Starting attempt 1 of 2
[2022-05-16 10:01:13,438] {taskinstance.py:1358} INFO - 
--------------------------------------------------------------------------------
[2022-05-16 10:01:13,460] {taskinstance.py:1377} INFO - Executing <Task(BashOperator): get_data_src_impacted_country_week_wise> on 2022-05-12 18:00:00+00:00
[2022-05-16 10:01:13,470] {standard_task_runner.py:52} INFO - Started process 560 to run task
[2022-05-16 10:01:13,473] {standard_task_runner.py:79} INFO - Running: ['***', 'tasks', 'run', 'Collect_Data_Dag', 'get_data_src_impacted_country_week_wise', 'scheduled__2022-05-12T18:00:00+00:00', '--job-id', '162', '--raw', '--subdir', 'DAGS_FOLDER/collect_data_dag.py', '--cfg-path', '/tmp/tmpbo4jrssk', '--error-file', '/tmp/tmptn1fyj15']
[2022-05-16 10:01:13,477] {standard_task_runner.py:80} INFO - Job 162: Subtask get_data_src_impacted_country_week_wise
[2022-05-16 10:01:13,561] {task_command.py:369} INFO - Running <TaskInstance: Collect_Data_Dag.get_data_src_impacted_country_week_wise scheduled__2022-05-12T18:00:00+00:00 [running]> on host 6c2369487cbf
[2022-05-16 10:01:13,851] {taskinstance.py:1571} INFO - Exporting the following env vars:
AIRFLOW_CTX_DAG_OWNER=Airflow
AIRFLOW_CTX_DAG_ID=Collect_Data_Dag
AIRFLOW_CTX_TASK_ID=get_data_src_impacted_country_week_wise
AIRFLOW_CTX_EXECUTION_DATE=2022-05-12T18:00:00+00:00
AIRFLOW_CTX_TRY_NUMBER=1
AIRFLOW_CTX_DAG_RUN_ID=scheduled__2022-05-12T18:00:00+00:00
[2022-05-16 10:01:13,855] {subprocess.py:62} INFO - Tmp dir root location: 
 /tmp
[2022-05-16 10:01:13,858] {subprocess.py:74} INFO - Running command: ['bash', '-c', 'python3 /opt/***/dags/scripts/dag_data_source_api_7.py']
[2022-05-16 10:01:13,912] {subprocess.py:85} INFO - Output:
[2022-05-16 10:07:31,612] {local_task_job.py:84} ERROR - Received SIGTERM. Terminating subprocesses
[2022-05-16 10:07:31,682] {process_utils.py:129} INFO - Sending Signals.SIGTERM to group 560. PIDs of all processes in the group: [563, 560]
[2022-05-16 10:07:31,686] {process_utils.py:80} INFO - Sending the signal Signals.SIGTERM to group 560
[2022-05-16 10:07:31,716] {taskinstance.py:1541} ERROR - Received SIGTERM. Terminating subprocesses.
[2022-05-16 10:07:31,764] {subprocess.py:103} INFO - Sending SIGTERM signal to process group
[2022-05-16 10:07:31,949] {taskinstance.py:1889} ERROR - Task failed with exception
Traceback (most recent call last):
  File "/home/airflow/.local/lib/python3.7/site-packages/airflow/operators/bash.py", line 189, in execute
    cwd=self.cwd,
  File "/home/airflow/.local/lib/python3.7/site-packages/airflow/hooks/subprocess.py", line 90, in run_command
    for raw_line in iter(self.sub_process.stdout.readline, b''):
  File "/home/airflow/.local/lib/python3.7/site-packages/airflow/models/taskinstance.py", line 1543, in signal_handler
    raise AirflowException("Task received SIGTERM signal")
airflow.exceptions.AirflowException: Task received SIGTERM signal
[2022-05-16 10:07:31,995] {taskinstance.py:1400} INFO - Marking task as UP_FOR_RETRY. dag_id=Collect_Data_Dag, task_id=get_data_src_impacted_country_week_wise, execution_date=20220512T180000, start_date=20220516T100113, end_date=20220516T100731
[2022-05-16 10:07:32,053] {standard_task_runner.py:97} ERROR - Failed to execute job 162 for task get_data_src_impacted_country_week_wise (Task received SIGTERM signal; 560)
[2022-05-16 10:07:32,167] {process_utils.py:75} INFO - Process psutil.Process(pid=563, status='terminated', started='10:01:12') (563) terminated with exit code None
[2022-05-16 10:07:32,171] {process_utils.py:75} INFO - Process psutil.Process(pid=560, status='terminated', exitcode=1, started='10:01:12') (560) terminated with exit code 1
[2022-05-16 10:07:32,173] {local_task_job.py:156} INFO - Task exited with return code 143
[2022-05-16 10:07:32,677] {local_task_job.py:273} INFO - 0 downstream tasks scheduled from follow-on schedule check
