[2022-05-12 07:41:27,519] {taskinstance.py:1159} INFO - Dependencies all met for <TaskInstance: Update_Country_Dag.correct_country_in_database manual__2022-05-12T07:41:26.223030+00:00 [queued]>
[2022-05-12 07:41:27,526] {taskinstance.py:1159} INFO - Dependencies all met for <TaskInstance: Update_Country_Dag.correct_country_in_database manual__2022-05-12T07:41:26.223030+00:00 [queued]>
[2022-05-12 07:41:27,527] {taskinstance.py:1356} INFO - 
--------------------------------------------------------------------------------
[2022-05-12 07:41:27,528] {taskinstance.py:1357} INFO - Starting attempt 1 of 2
[2022-05-12 07:41:27,529] {taskinstance.py:1358} INFO - 
--------------------------------------------------------------------------------
[2022-05-12 07:41:27,540] {taskinstance.py:1377} INFO - Executing <Task(BashOperator): correct_country_in_database> on 2022-05-12 07:41:26.223030+00:00
[2022-05-12 07:41:27,545] {standard_task_runner.py:52} INFO - Started process 1241 to run task
[2022-05-12 07:41:27,548] {standard_task_runner.py:79} INFO - Running: ['***', 'tasks', 'run', 'Update_Country_Dag', 'correct_country_in_database', 'manual__2022-05-12T07:41:26.223030+00:00', '--job-id', '10', '--raw', '--subdir', 'DAGS_FOLDER/update_country_dag.py', '--cfg-path', '/tmp/tmpq928zhck', '--error-file', '/tmp/tmpd7lod8kd']
[2022-05-12 07:41:27,551] {standard_task_runner.py:80} INFO - Job 10: Subtask correct_country_in_database
[2022-05-12 07:41:27,590] {task_command.py:369} INFO - Running <TaskInstance: Update_Country_Dag.correct_country_in_database manual__2022-05-12T07:41:26.223030+00:00 [running]> on host c5e465c36164
[2022-05-12 07:41:27,630] {taskinstance.py:1571} INFO - Exporting the following env vars:
AIRFLOW_CTX_DAG_OWNER=Airflow
AIRFLOW_CTX_DAG_ID=Update_Country_Dag
AIRFLOW_CTX_TASK_ID=correct_country_in_database
AIRFLOW_CTX_EXECUTION_DATE=2022-05-12T07:41:26.223030+00:00
AIRFLOW_CTX_TRY_NUMBER=1
AIRFLOW_CTX_DAG_RUN_ID=manual__2022-05-12T07:41:26.223030+00:00
[2022-05-12 07:41:27,632] {subprocess.py:62} INFO - Tmp dir root location: 
 /tmp
[2022-05-12 07:41:27,633] {subprocess.py:74} INFO - Running command: ['bash', '-c', 'python3 /opt/***/dags/update_country.py']
[2022-05-12 07:41:27,640] {subprocess.py:85} INFO - Output:
[2022-05-12 07:41:27,690] {subprocess.py:92} INFO - Traceback (most recent call last):
[2022-05-12 07:41:27,691] {subprocess.py:92} INFO -   File "/opt/***/dags/update_country.py", line 3, in <module>
[2022-05-12 07:41:27,692] {subprocess.py:92} INFO -     import pymongo
[2022-05-12 07:41:27,692] {subprocess.py:92} INFO - ModuleNotFoundError: No module named 'pymongo'
[2022-05-12 07:41:27,693] {subprocess.py:96} INFO - Command exited with return code 1
[2022-05-12 07:41:27,704] {taskinstance.py:1889} ERROR - Task failed with exception
Traceback (most recent call last):
  File "/home/airflow/.local/lib/python3.7/site-packages/airflow/operators/bash.py", line 195, in execute
    f'Bash command failed. The command returned a non-zero exit code {result.exit_code}.'
airflow.exceptions.AirflowException: Bash command failed. The command returned a non-zero exit code 1.
[2022-05-12 07:41:27,711] {taskinstance.py:1400} INFO - Marking task as UP_FOR_RETRY. dag_id=Update_Country_Dag, task_id=correct_country_in_database, execution_date=20220512T074126, start_date=20220512T074127, end_date=20220512T074127
[2022-05-12 07:41:27,862] {standard_task_runner.py:97} ERROR - Failed to execute job 10 for task correct_country_in_database (Bash command failed. The command returned a non-zero exit code 1.; 1241)
[2022-05-12 07:41:27,895] {local_task_job.py:156} INFO - Task exited with return code 1
[2022-05-12 07:41:27,914] {local_task_job.py:273} INFO - 0 downstream tasks scheduled from follow-on schedule check
